{
 "cells": [
  {
   "cell_type": "markdown",
   "metadata": {},
   "source": [
    "# Basic Unit Tests"
   ]
  },
  {
   "cell_type": "code",
   "execution_count": 1,
   "metadata": {},
   "outputs": [],
   "source": [
    "assert sum([1, 2, 3]) == 6, \"Should be 6\""
   ]
  },
  {
   "cell_type": "code",
   "execution_count": 2,
   "metadata": {},
   "outputs": [
    {
     "ename": "AssertionError",
     "evalue": "Should be 6",
     "output_type": "error",
     "traceback": [
      "\u001b[1;31m---------------------------------------------------------------------------\u001b[0m",
      "\u001b[1;31mAssertionError\u001b[0m                            Traceback (most recent call last)",
      "Cell \u001b[1;32mIn[2], line 1\u001b[0m\n\u001b[1;32m----> 1\u001b[0m \u001b[38;5;28;01massert\u001b[39;00m \u001b[38;5;28msum\u001b[39m([\u001b[38;5;241m1\u001b[39m, \u001b[38;5;241m1\u001b[39m, \u001b[38;5;241m1\u001b[39m]) \u001b[38;5;241m==\u001b[39m \u001b[38;5;241m6\u001b[39m, \u001b[38;5;124m\"\u001b[39m\u001b[38;5;124mShould be 6\u001b[39m\u001b[38;5;124m\"\u001b[39m\n",
      "\u001b[1;31mAssertionError\u001b[0m: Should be 6"
     ]
    }
   ],
   "source": [
    "assert sum([1, 1, 1]) == 6, \"Should be 6\""
   ]
  },
  {
   "cell_type": "markdown",
   "metadata": {},
   "source": [
    "# Test Results\n",
    "\n",
    "For the tests above, the fact that the first one ran successfully means the sum function works as intended, and the second test failing means that the sum function does not work the way we want it to.\n",
    "\n",
    "Here is the output when executing the test.py file I created for this assignment:\n",
    "```\n",
    "F.\n",
    "======================================================================\n",
    "FAIL: test_list_fraction (__main__.TestSum.test_list_fraction)\n",
    "Test that it can sum a list of fractions\n",
    "----------------------------------------------------------------------\n",
    "Traceback (most recent call last):\n",
    "  File \"c:\\Users\\gabri\\Documents\\GitHub\\M01-Collaboration\\unit-testing\\test.py\", line 22, in test_list_fraction  \n",
    "    self.assertEqual(result, 1)\n",
    "AssertionError: Fraction(9, 10) != 1\n",
    "\n",
    "----------------------------------------------------------------------\n",
    "Ran 2 tests in 0.003s\n",
    "\n",
    "FAILED (failures=1)\n",
    "```\n",
    "\n",
    "It shows that the `test_list_fraction` case is failing, meaning the `Fraction` function either does not behave the way we intended it to, or the test was not setup incorrectly."
   ]
  }
 ],
 "metadata": {
  "kernelspec": {
   "display_name": "Python 3",
   "language": "python",
   "name": "python3"
  },
  "language_info": {
   "codemirror_mode": {
    "name": "ipython",
    "version": 3
   },
   "file_extension": ".py",
   "mimetype": "text/x-python",
   "name": "python",
   "nbconvert_exporter": "python",
   "pygments_lexer": "ipython3",
   "version": "3.12.2"
  }
 },
 "nbformat": 4,
 "nbformat_minor": 2
}
